Workbook
Name Andrew: #REF!
Name Availability: [1]B4!$D$53:$D$56
Name Bidder_and_Sub: [2]ControlSheet!$A$3:$A$13
Name csDesignMode: 1
Name CustomizationEffort: [1]B4!$D$58:$D$61
Name Department_Function: '[3]HR Process Questions'!#REF!
Name Effort: [4]Metadata!$F$2:$F$5
Name EY: #REF!
Name G1Ref: #REF!
Name G2Ref: #REF!
Name MainBidder: [2]C1!$D$7
Name ProductModules: [1]ControlSheet!$K$3:$K$56
Name ProjectRoles: [2]ControlSheet!$C$3:$C$26
Name Rank: '[5]Data Validation'!$A$1:$A$4
Name Response: [4]Metadata!$A$2:$A$6
Name review: #REF!
Name reviewers: #REF!
Name reviewers2: #REF!
Name Slicer_Domain_ID1: #N/A
Name Slicer_Domain_ID11: #N/A
Name SubsList: #REF!
Name Time0: #REF!
Name Time1: #REF!
Name Time2: #REF!
Name Value1: #REF!
Name Value2: #REF!
Name x: #REF!

Sheet Cover
C16: Saudi Air Navigation Services
C18: NDMO & NDI Questionnaire for Data Management
D20: Date: | E20: 13/11/2025 | K20: Version: | L20: 1

Sheet Priority Items
A4: Domain Name | B4: Domain ID | C4: NDI Q# | D4: Maturity Level | E4: Level No. | F4: Evidence | G4: Acceptance Criteria | H4: Priority | I4: NDMO Specifications | J4: NDI ID | K4: Meets NDMO criteria? | L4: Meets NDI Criteria? | M4: Compliance Validation Flag | N4: Comments | O4: Evidence Document Name | P4: Current Stakeholders | Q4: Order
M8: 1
M19: 1
M36: 1
M43: 1
M47: 1
A73: Data Sharing and Interoperability | B73: DSI | C73: DSI.MQ.1 | D73: Establishing | E73: 1 | F73: The Updated and Approved Results of the Initial Data Integration Assessment. | G73: The Entity must attach the report of the Data Integration assessment results, including the following, as a minimum: • The current IT Structure: an inventory of all existing IT components (data sources, systems, applications and data stores). • High Level Data Lineage including the rules according to which data is changed, and the frequency of changes. • Data Models used by the Entity's IT components. • List of all identified challenges in the Data Lineage of data movements and integration. | H73: N/A | I73: DSI.1.1 | J73: DSI.C.1.1 | K73: Under Development | L73: Partially | N73: Does not cover all requirements | O73: Integration_assessment | P73: Information Technology Data Management | Q73: 69
A74: Data Sharing and Interoperability | B74: DSI | C74: DSI.MQ.1 | D74: Defined | E74: 2 | F74: The Developed Data Integration Strategy Document. | G74: The entity must attach the developed Data Integration Strategy containing the following, at a minimum:  The Strategy’s approval by the entity’s authority holder and effective date.  The Strategy must be recent (Approved within the last three years).  The objectives, initiatives, projects and the metric indicators of the implementation of the Data Integration activities and milestones. The activities shall incorporate what is needed to achieve this Domain’s specifications, at a minimum.  The implementation roadmap of the Data Integration initiatives.  The assignment of the required resources & budget allocation to manage the implementation of this Domain. | H74: N/A | I74: N/A | J74: DSI.M.2 | K74: N/A | L74: No | P74: Information Technology Data Management | Q74: 70
A75: Data Sharing and Interoperability | B75: DSI | C75: DSI.MQ.1 | D75: Defined | E75: 2 | F75: The Developed Target Data Integration Architecture. | G75: The Entity must attach the Target Data Integration Architecture including the following, as a minimum: • The Data Integration requirements. • The Data Integration Architecture diagram. • The Architecture components. | H75: P1 | I75: DSI.1.2 | J75: DSI.C.1.2 | K75: No | L75: No | P75: Information Technology Data Management | Q75: 71
A76: Data Sharing and Interoperability | B76: DSI | C76: DSI.MQ.1 | D76: Defined | E76: 2 | F76: The Developed Data Integration Plan (Including Data Sharing Activities). | G76: The Entity must attach the developed Data Integration Plan including the following, as a minimum: • The summarized Architecture briefs. • The roadmap and covenant charters of the projects and initiatives in the plan. • The assignment of the required resources & budget allocation for the projects and initiatives in the plan. | H76: P1 | I76: DSI.1.3 | J76: DSI.C.1.3 | K76: Under Development | L76: Partially | N76: Roadmap needs to be updated to include summarized architecture briefs | O76: SANS-CYB-DM-PL-02-SANS-Data Strategic Requirements and Data- Ver.1.0 Mar 2024 | P76: Information Technology Data Management | Q76: 72
M85: 1
M87: 1
M88: 1
M89: 1
M94: 1
M95: 1
M97: 1
A101: Data Sharing and Interoperability | B101: DSI | C101: DSI.MQ.3 | D101: Defined | E101: 2 | F101: The Integration Requirements Document. | G101: The Entity must attach the Integration / Interoperability Requirements document containing the following, as a minimum: • A clearly defined scope. • Entity's Business goals / objectives and aims to be achieved. • Implementation Timeline. • Resources required. • Cost estimate. • Functional requirements. • Non-Functional requirements. | H101: P1 | I101: DSI.3.1 | J101: DSI.C.3.1 | K101: Yes | L101: Yes | O101: ICD_Diplomatic Clearance System (DCS) (DSI.MQ.3), SANS-RAC-ICD-AODB-FDS V0.1- 05 Nov 2023 (DSI.MQ.3) | P101: Information Technology Data Management | Q101: 97
A102: Data Sharing and Interoperability | B102: DSI | C102: DSI.MQ.3 | D102: Defined | E102: 2 | F102: The Solution Design Document. | G102: The Entity must attach the Solution Design document including the following, as a minimum: • Integration Solution Overview. • Target Data Integration Architecture. • Data Orchestration – The Data Flow Diagram (DFD). • Source to Target Mapping – A set of Data Transformation instructions that determine how to convert the structure and content of Data in the source system to the structure and content needed in the target system. The instructions shall include the following, as a minimum: ◦ The technical format of Data at the source and the target. ◦ The Specifications of transformations required for all intermediate staging points between the source and the target. | H102: P1 | I102: DSI.3.2 | J102: DSI.C.3.2 | K102: No | L102: No | N102: The provided evidence does not align with NDI requirements. (e.g. source to target mapping, data flows.are missing) | O102: ICD_Diplomatic Clearance System (DCS) (DSI.MQ.3), SANS-RAC-ICD-AODB-FDS V0.1- 05 Nov 2023 (DSI.MQ.3) | P102: Information Technology Data Management | Q102: 98
M105: 1
A109: Data Sharing and Interoperability | B109: DSI | C109: DSI.MQ.4 | D109: Establishing | E109: 1 | F109: The Existing Data Integration or Data Movement Processes within the Entity. | G109: The Entity must attach a report on the current Data Integration / Interoperability Processes or the current Data Movement Processes within the Entity. | H109: N/A | I109: N/A | J109: DSI.M.20 | K109: N/A | L109: Yes | O109: Integration_assessment, SANS Data Achitecture Assessment v1.0 | P109: Information Technology Data Management | Q109: 105
A110: Data Sharing and Interoperability | B110: DSI | C110: DSI.MQ.4 | D110: Defined | E110: 2 | F110: The Developed Data Migration Processes (i.e.: ETL). | G110: The Entity must attach a report on the Processes and Standards process to integrate data from disparate sources and load it into the Data Warehouse Store i.e.: Extract, Transform, Load (ETL). | H110: P2 | I110: DSI.4.1 | J110: DSI.C.4.1.1 | K110: No | L110: No | M110: 1 | N110: The provided document is a data sharing request letter. It is not relevant to the evidence required here. | O110: GACA Forecast Data Request - Letter (DSI.MQ.4) | P110: Information Technology Data Management | Q110: 106
A111: Data Sharing and Interoperability | B111: DSI | C111: DSI.MQ.4 | D111: Defined | E111: 2 | F111: The Developed Data Migration Processes (i.e.: ELT). | G111: The Entity must attach a report on the Processes and Standards process to store the unstructured data in its raw native format in the Data Lake i.e.: Extract, Load, Transform (ELT). | H111: P2 | I111: DSI.4.2 | J111: DSI.C.4.2.1 | K111: No | L111: No | M111: 1 | P111: Information Technology Data Management | Q111: 107
A113: Data Sharing and Interoperability | B113: DSI | C113: DSI.MQ.4 | D113: Defined | E113: 2 | F113: The Defined Data Sharing Controls. | G113: The Entity must attach a report on the Controls that have been identified and defined for Data Sharing. | H113: N/A | I113: N/A | J113: DSI.M.22 | K113: N/A | L113: No | P113: Data Governance & Protection Information Technology Data Management | Q113: 109
M115: 1
M116: 1
A119: Data Quality | B119: DQ | C119: DQ.MQ.1 | D119: Establishing | E119: 1 | F119: Evidence of the Existing Data Quality (DQ) Related Activities. | G119: The Entity must attach a report on the activities that are practiced in the DQ Domain. For each activity, the report must contain the following, as a minimum: • Copies / screenshots of e-mail correspondences which support practicing the activity. • Copies / screenshots of documents which support practicing the activity. • Screenshots of the systems which support practicing the activity. | H119: N/A | I119: N/A | J119: DQ.M.1 | K119: N/A | L119: Yes | O119: DQ.MQ.1-3 ticket1, DQ.MQ.1-3 ticket1_1 | P119: Safety Quality & Compliance Data Management | Q119: 115
A120: Data Quality | B120: DQ | C120: DQ.MQ.1 | D120: Defined | E120: 2 | F120: The Defined and Approved DQ Implementation Plan. | G120: The Entity must attach a defined and approved DQ management plan to implement and manage the activities which aim at improving the Entity’s Data. This plan must contain the following, as a minimum: • A roadmap that includes the activities and milestones of implementing the DQ Management practices in the Entity. The activities shall incorporate what is needed to achieve this Domain’s specifications, as a minimum. • The assignment of the required resources & budget allocation to manage the implementation of the DQ Management Plan. | H120: P1 | I120: DQ.1.2 | J120: DQ.C.1.2 | K120: Yes | L120: Yes | O120: SANS-CYB-DM-PL-01-SANS-Data Strategy Roadmap & Investment Plan- Ver.1.0 Mar 2024, Page # 56 | P120: Data Governance & Protection Safety Quality & Compliance Data Management | Q120: 116
A126: Data Quality | B126: DQ | C126: DQ.MQ.2 | D126: Establishing | E126: 1 | F126: The Existing DQ Domain Initiatives. | G126: The Entity must attach a report on the current DQ Domain initiatives. | H126: N/A | I126: N/A | J126: DQ.M.7 | K126: N/A | L126: Yes | O126: SANS-CYB-DM-PL-01-SANS-Data Strategy Roadmap & Investment Plan- Ver.1.0 Mar 2024, Page # 56 | P126: Safety Quality & Compliance Data Management | Q126: 122
A127: Data Quality | B127: DQ | C127: DQ.MQ.2 | D127: Establishing | E127: 1 | F127: The Existing Processes for Detecting DQ Issues. | G127: The Entity must attach a report on the current DQ issue detection processes. | H127: N/A | I127: N/A | J127: DQ.M.8 | K127: N/A | L127: No | N127: The evidence provided lacks the required information on DQ issue detection and correction processes. | O127: DQ.MQ.1-3 ticket1 DQ.MQ.1-3 ticket1_1 | P127: Safety Quality & Compliance Data Management | Q127: 123
A128: Data Quality | B128: DQ | C128: DQ.MQ.2 | D128: Establishing | E128: 1 | F128: The Existing Processes Used for Data Corrections or Data Validations. | G128: The Entity must attach a report on the current processes used for Data corrections or Data validations. | H128: N/A | I128: N/A | J128: DQ.M.9 | K128: N/A | L128: No | N128: The evidence provided lacks the required information on DQ issue detection and correction processes. | O128: DQ.MQ.1-3 ticket1 DQ.MQ.1-3 ticket1_1 | P128: Safety Quality & Compliance Data Management | Q128: 124
A129: Data Quality | B129: DQ | C129: DQ.MQ.2 | D129: Defined | E129: 2 | F129: The Prioritized List of Data Elements. | G129: The Entity must attach a report listing the Data elements ranked / prioritized based on business requirements. The first priority Data must include the Entity’s Master Data, as a minimum. | H129: P1 | I129: DQ.1.1 | J129: DQ.C.1.1 | K129: No | L129: No | P129: Safety Quality & Compliance Data Management | Q129: 125
A130: Data Quality | B130: DQ | C130: DQ.MQ.2 | D130: Defined | E130: 2 | F130: The Defined DQ Dimensions for the Entity's Datasets. | G130: The Entity must attach a report clarifying the defined DQ Dimensions for the Entity's Datasets including the following, as a minimum: • Completeness (The degree of how complete data records are). • Uniqueness (The degree of how unique data records are without duplicates). • Timeliness (The degree to which data is up to date and available when it is needed). • Validity (The degree of records' conformance to the established formats, types and ranges). • Accuracy (The degree to which data values align to real values). • Consistency (The degree to which data is consistent across the Entity’s business and across different sources). | H130: P2 | I130: DQ.2.1 | J130: DQ.C.2.1 | K130: No | L130: No | P130: Safety Quality & Compliance Data Management | Q130: 126
A131: Data Quality | B131: DQ | C131: DQ.MQ.2 | D131: Defined | E131: 2 | F131: The Data Quality Rules Report. | G131: The Entity must attach a report clarifying the list of defined DQ Rules that are aligned with the DQ Dimensions including the following, as a minimum: • The DQ rule owner. • The business description of the requirement to be validated by the rule. • Regarding the particular data whose quality is being measured: The assignment of Rules to each of the DQ Dimensions including the following, as a minimum: ◦ Completeness. ◦ Uniqueness. ◦ Timeliness. ◦ Validity. ◦ Accuracy. ◦ Consistency. • The list of Data Attributes validated by the defined rules. • The metrics that are calculated when validating each DQ rule. • The escalation threshold that triggers a DQ alert for the rule. | H131: P2 | I131: DQ.2.2 | J131: DQ.C.2.1.2 | K131: No | L131: No | M131: 1 | P131: Safety Quality & Compliance Data Management | Q131: 127
A132: Data Quality | B132: DQ | C132: DQ.MQ.2 | D132: Defined | E132: 2 | F132: The Developed & Approved Processes for DQ Issue Management & Remediation. | G132: The Entity must attach a report clarifying the Developed & Approved Processes for DQ Issue Management & Remediation followed for DQ issue management & remediation / resolution including, as a minimum, the following: • The development of a remediation plan. The remediation plan must include the following, as a minimum: • A "Root Cause" analysis to determine the causes of the identified DQ issue. • An Impact analysis to assess the negative consequences and determine an issue level (whether it is local / limited, or at the Entity level). • The definition & identification of the DQ Targets set for each of the issues & challenges, related to each DQ Dimension, depending on the context of the issue / challenge within the Entity. • The definition & identification of the options for resolving the issue's "Root Cause", including a feasibility analysis. • The specifications of the Data Cleansing process to be performed if the solution does not correct the "Root Cause" of the DQ issue. • The decision & the logical rationale for selecting the specific option (chosen) to solve the issue. • The implementation status of the issue's most suitable resolution choice (including any change). • The review of the implemented resolution and a verification that the issue is resolved. • Establishing & developing a roadmap and milestones for the resolution of the noticed & identified DQ issues. • Allocating the necessary resources to implement the DQ issue identification plan. | H132: P2 | I132: DQ.2.3 | J132: DQ.C.2.3.1 | K132: Under Development | L132: Partially | M132: 1 | N132: Data quality activities are conducted reactively, lacking formalized data quality practices and standards | P132: Safety Quality & Compliance Data Management | Q132: 128
A133: Data Quality | B133: DQ | C133: DQ.MQ.2 | D133: Activated | E133: 3 | F133: The Planned & Conducted Initial & Periodic Data Quality Assessment Report. | G133: The Entity must attach a report clarifying the initial & periodic DQ assessment, which was planned for and conducted (already). The assessment must include the following, as a minimum: • Collecting business requirements for the Quality of Data in the scope. • Establishing & defining DQ Rules based on the collected business requirements specifically. • Performing a check by Data Profiling based on the Predefined DQ Rules. • Reporting the discovered and identified DQ comments & issues to the concerned / relevant department in the Entity. • Developing plans (with key milestones) for resolving the discovered & identified DQ issues. | H133: P1 | I133: DQ.1.3 | J133: DQ.C.1.3 | K133: No | L133: No | P133: Safety Quality & Compliance Data Management | Q133: 129
M134: 1
A144: Data Quality | B144: DQ | C144: DQ.MQ.3 | D144: Establishing | E144: 1 | F144: The Existing DQ Monitoring Practices. | G144: The Entity must attach an updated & approved report clarifying the Entity’s current DQ monitoring practices. | H144: N/A | I144: N/A | J144: DQ.M.16 | K144: N/A | L144: No | N144: DQ.MQ.1-3 ticket1, DQ.MQ.1-3 ticket1_1 | O144: The evidence provided lacks information on the current Data Quality monitoring practices (i.e., number of issues detected, validated, resolved and the status of open DQ issues) | P144: Safety Quality & Compliance Data Management | Q144: 140
A145: Data Quality | B145: DQ | C145: DQ.MQ.3 | D145: Establishing | E145: 1 | F145: Evidence of the Entity's Current DQ Status. | G145: The Entity must attach an updated & approved report showing the current DQ situation. | H145: N/A | I145: N/A | J145: DQ.M.17 | K145: N/A | L145: No | N145: DQ.MQ.1-3 ticket1, DQ.MQ.1-3 ticket1_1 | O145: The evidence provided lacks information on the current Data Quality monitoring practices (i.e., number of issues detected, validated, resolved and the status of open DQ issues) | P145: Safety Quality & Compliance Data Management | Q145: 141
A146: Data Quality | B146: DQ | C146: DQ.MQ.3 | D146: Defined | E146: 2 | F146: The Defined and Formalized DQ Monitoring Plan. | G146: The Entity must attach the defined DQ monitoring plan showing activities required to monitor and document the data quality status on a regular with the assigned resources for implementation. | H146: P2 | I146: DQ.2.2 | J146: DQ.C.2.2.1 | K146: No | L146: No | M146: 1 | P146: Safety Quality & Compliance Data Management | Q146: 142
...

Sheet Master
A4: Domain Name | B4: Domain ID | C4: NDI Q# | D4: Maturity Level | E4: Level No. | F4: Evidence | G4: Acceptance Criteria | H4: Priority | I4: NDMO Specifications | J4: NDI ID | K4: Meets NDMO criteria? | L4: Meets NDI Criteria? | M4: Compliance Validation Flag | N4: Comments | O4: Evidence Document Name | P4: Current Stakeholders
A5: Data Governance | B5: DG | C5: DG.MQ.1 | D5: Establishing | E5: 1 | F5: Existing data-related practices. | G5: Attach a report showing current data practices. | H5: N/A | I5: N/A | J5: DG.M.1 | K5: N/A | L5: Yes | O5: SANS-CYB-DM-PL-02-SANS-Data Strategic Requirements and Data- Ver.1.0 Mar 2024 | P5: Data Governance & Protection
A6: Data Governance | B6: DG | C6: DG.MQ.1 | D6: Defined | E6: 2 | F6: The approved DM & PDP Strategy. | G6: Attach the Data Management and Personal Data Protection (DM & PDP) Strategy which must be approved & includes the following, as a minimum: • Current challenges in DM. • The Strategic requirements including: Internal requirements emanating from the Entity's business strategy and external requirements emanating from the National Strategy for DM & PDP. • The DM & PDP Vision, Mission, and Strategic Objectives. • Strategic and operational performance indicators with targets extending from 3 to 5 years over the strategy’s implementation duration. • The financial budget required to implement the strategy divided according to identified initiatives. | H6: P1 | I6: DG.1.1 | J6: DG.C.1.1 | K6: Yes | L6: Yes | N6: An approved data management strategy & roadmap in place, The initiatives must align with NDMO controls for effective strategy execution and compliance monitoring. | O6: SANS-CYB-DM-PL-02-SANS-Data Strategic Requirements and Data- Ver.1.0 Mar 2024 | P6: Data Governance & Protection
A7: Data Governance | B7: DG | C7: DG.MQ.1 | D7: Defined | E7: 2 | F7: The DM guiding principles. | G7: Attach a copy of the DM & PDP program guidelines, which may be a part of the Entity's DM & PDP Strategy doc or a separate doc. The guidelines must refer to the principles underlying the culture of DM & Data processing, to enable and spread a unified DM & PDP concept within the Entity itself. | H7: P1 | I7: DG.1.2 | J7: DG.C.1.2 | K7: Yes | L7: Yes | O7: SANS-CYB-DM-PL-03-Data Strategy Mandate - Ver.1.0 Mar 2024, Page # 31 | P7: Data Governance & Protection
A8: Data Governance | B8: DG | C8: DG.MQ.1 | D8: Defined | E8: 2 | F8: Data Strategy Approval Decision letter. | G8: Attach a copy of the entity-specific data strategy approval decision by the entity’s Data Management Committee or the entity’s authority holder | H8: P1 | I8: DG.1.4 | J8: DG.C.1.4.1 | K8: Yes | L8: Yes | M8: 1 | O8: SANS-CYB-DM-PL-03-Data Strategy Mandate - Ver.1.0 Mar 2024, Page # 2 Strategy and Requirements Socialization | P8: Data Governance & Protection
A9: Data Governance | B9: DG | C9: DG.MQ.1 | D9: Activated | E9: 3 | F9: - All level 2 acceptance evidence requirements including: - The developed DM & PDP implementation plan. | G9: Attach the implementation plan which must include, as a minimum: • Identified initiatives that covers all the DM domains. • A prioritized list of DM initiatives with descriptions. • A three-year Implementation roadmap to close the gaps identified between the current state and target state. | H9: P1 | I9: DG.1.3 | J9: DG.C.1.3 | K9: Yes | L9: Yes | N9: Roadmap needs to be updated to reflect current status | O9: SANS-CYB-DM-PL-01-SANS-Data Strategy Roadmap & Investment Plan- Ver.1.0 Mar 2024 | P9: Data Governance & Protection
A10: Data Governance | B10: DG | C10: DG.MQ.1 | D10: Activated | E10: 3 | F10: Implementation status report. | G10: Attach a report of the implementation status of DM and PDP plan, including, at a minimum:  Initiatives and projects status: Identifying the status of each initiative or project (started, in progress, completed, or delayed), along with clarification of any delays or challenges.  Progress percentages: Providing the progress percentages of activities and milestones in the plan and roadmap, with clear details on the actual activities that have been completed.  Supporting evidence: Attaching proof of achieved progress/completion, such as reports, photos, documents, or meeting minutes that support the implementation status. | H10: N/A | I10: N/A | J10: DG.M.2 | K10: N/A | L10: No | P10: Data Governance & Protection
A11: Data Governance | B11: DG | C11: DG.MQ.1 | D11: Managed | E11: 4 | F11: All level 3 acceptance evidence requirements including: - The monitoring report of the DM & PDP strategy & plan implementation based on the defined KPIs in the strategy & implementation plan. | G11: The report must be prepared based on the data of the Key Performance Indicators (KPIs) (Indicator Cards) which were Predefined in the DM & PDP strategic plan, and each indicator’s data or card should include the following, as a minimum: • Indicator’s Name / Code. • Indicator’s Owner. • Indicator’s Coordinator. • Indicator’s Description. • The strategic/operational objective to be measured (with identifying the Specification or the Process to which the indicator belongs). • Indicator’s Equation. • Measurement Unit (Percentage, Number / Quantity, etc.). • Baseline (Measurement value in the first measurement year). • Target value. • Measurement Periodicity (Monthly / Quarterly / Biannually / Annually). • Data sources used to calculate the indicator. • Data collection mechanism. • Indicator’s polarity (+/-) (Positive Polarity: Higher indicator value is the target, Negative Polarity: Lower indicator value is the target). • The current value of the indicator compared to the target value. • The status of the indicator (achieved/delayed/not achieved/etc). The report should also include: • Recommendations for performance improvement based on the actual values of the indicators. • Supporting documents for the data used to calculate the indicator values. | H11: N/A | I11: N/A | J11: DG.M.3 | K11: N/A | L11: No | P11: Data Governance & Protection
A12: Data Governance | B12: DG | C12: DG.MQ.1 | D12: Pioneer | E12: 5 | F12: All level 4 acceptance evidence requirements including: - A report demonstrating the entity's monitoring of the latest DM practices and updating of the implementation plan based on these practices and changes in business requirements. | G12: Attach a report showing that the entity identified, implemented and has been monitoring the continuous improvement mechanisms for DM & PDP plan. The report shall include the following:  The updated DM & PDP strategy.  The updated DG practices that include the Data Management Organization, the roles, the processes, & the technologies.  The continuous improvement mechanisms for all DM Domains. | H12: P2 | I12: DG.6.1 | J12: DG.C.6.1 | K12: No | L12: No | P12: Data Governance & Protection
A13: Data Governance | B13: DG | C13: DG.MQ.1 | D13: Pioneer | E13: 5 | F13: A report demonstrating the entity's monitoring of the latest DM practices and updating of the strategy based on these practices and changes in business requirements. | G13: Attach a report showing that the entity identified, implemented and has been monitoring the continuous improvement mechanisms for DM & PDP strategy. The report shall include the following:  The documented periodic DM & PDP reviews & results.  Documented changes to the initial approved plan where applicable. | H13: P2 | I13: DG.7.2 | J13: DG.C.7.2 | K13: Under Development | L13: Partially | N13: The KPIs have been defined as part of the strategy, however the KPIs are not tracked | P13: Data Governance & Protection
A14: Data Governance | B14: DG | C14: DG.MQ.2 | D14: Establishing | E14: 1 | F14: The Data Management & Personal Data Protection (DM & PDP) Policies, Controls and Guidelines Gap Analysis document. | G14: The gap analysis document shall include the following as a minimum: • An analysis of DM & PDP Standards and Guidelines established by the National Data Management Office (NDMO). • Identifying & analyzing all Data-related policies & controls published by the Oversight Entities & the regulator(s) of the sector to which the Entity belongs. • An analysis of the Entity's internal requirements for DM & PDP Controls. • Recommendations and suggestions to close the gaps identified as well a specific list of policies that the Entity will develop in line with the Policies published by NDMO-SDAIA. • A plan to develop DM & PDP policies and controls, clearly presenting the implementation timeline. | H14: P1 | I14: DG.2.1 | J14: DG.C.2.1 | K14: Yes | L14: Yes | N14: All documentation mentioned. Timeline to update dm & pdp policies part of the overall roadmap (Roadmap needs to be updated) | O14: SANS-CYB-DM-PL-02-SANS-Data Strategic Requirements and Data- Ver.1.0 Mar 2024 (previously) SANS Current State Assessment Report (Latest) | P14: Data Governance & Protection
A15: Data Governance | B15: DG | C15: DG.MQ.2 | D15: Defined | E15: 2 | F15: All level 1 acceptance evidence requirements including: - The policies, standards, and guidelines developed by the entity for all DM domains. | G15: The entity should develop policies covering all DM domains, as well as standards and guidelines as needed. The policies should be approved by the Data Management and Governance Committee and every policy’s document shall include, the following, at a minimum:  Policy Name.  Release date.  Version number.  Document control (Preparation, review, approval).  Version history.  Terminology.  Goal.  Scope of work.  Guiding Principles  Policy Statement.  Job roles & responsibilities.  Related Policies.  References.  Policy Owner. - The entity should attach the policies approval evidence. | H15: P1 | I15: DG.2.2 | J15: DG.C.2.2 | K15: Under Development | L15: Partially | N15: Limited policies exists for 4 domains and not implemented | P15: Data Governance & Protection
A16: Data Governance | B16: DG | C16: DG.MQ.2 | D16: Activated | E16: 3 | F16: All level 2 acceptance evidence requirements including: - Implementation status report. | G16: Attach the policies implementation status report, showing the percentages of progress in developing the processes and procedures related to policy implementation. | H16: N/A | I16: N/A | J16: DG.M.4 | K16: N/A | L16: No | P16: Data Governance & Protection
A17: Data Governance | B17: DG | C17: DG.MQ.2 | D17: Activated | E17: 3 | F17: A document proving the Entity's approval & adoption of the developed policies, standards & guidelines. | G17: Attach a report showing the dissemination and communication of all developed policies to the relevant stakeholders of each policy (e.g., email notifications sent to relevant stakeholders to introduce the approved policies or through the entity’s official portal, etc.). | H17: N/A | I17: N/A | J17: DG.M.5 | K17: N/A | L17: No | P17: Data Governance & Protection
A18: Data Governance | B18: DG | C18: DG.MQ.2 | D18: Activated | E18: 3 | F18: Approved Compliance Management Framework. | G18: Attach the Compliance Framework, detailing the following: • The scope of the compliance audit’s periodic procedure. • The processes needed to plan and perform the compliance audit procedure. • The processes & tools needed for reporting a compliance audit results. • The processes & plans for remediating & escalating non-compliance cases. | H18: P2 | I18: DG.5.1 | J18: DG.C.5.1 | K18: Under Development | L18: Partially | N18: A draft version of compliance framework is avaiable | P18: Data Governance & Protection
A19: Data Governance | B19: DG | C19: DG.MQ.2 | D19: Managed | E19: 4 | F19: All level 3 acceptance evidence requirements including: - Monitoring reports on the developed policies and standards, based on the pre-defined KPIs related to these policies and standards, as outlined in the DM strategy and implementation plan. | G19: The entity should attach an updated report, approved by the entity’s authority holder, to monitor the performance status of the developed policies and standards based on the identified and pre-defined Key Performance Indicators (KPIs) and scorecards. Each indicator’s card should include the following at a minimum: • Indicator’s Name / Code. • Indicator’s Owner. • Indicator’s Coordinator. • Indicator’s Description. • The strategic/operational objective to be measured (with identifying the Specification or the Process to which the indicator belongs). • Indicator’s Equation. • Measurement Unit (Percentage, Number / Quantity, etc.). • Baseline (Measurement value in the first measurement year). • Target value. • Measurement Periodicity (Monthly / Quarterly / Biannually / Annually). • Data sources used to calculate the indicator. • Data collection mechanism. • Indicator’s polarity (+/-) (Positive Polarity: Higher indicator value is the target, Negative Polarity: Lower indicator value is the target). • The current value of the indicator compared to the target value. • The status of the indicator (achieved/delayed/not achieved/etc). The report should also include: • Recommendations for performance improvement based on the actual values of the indicators. • Supporting documents for the data used to calculate the indicator values. | H19: P2 | I19: DG.7.1 (3 & 6) | J19: DG.C.7.1.1 | K19: Under Development | L19: Partially | M19: 1 | N19: The KPIs have been defined as part of the strategy, however the KPIs are not tracked | P19: Data Governance & Protection
A20: Data Governance | B20: DG | C20: DG.MQ.2 | D20: Managed | E20: 4 | F20: The Entity's Compliance Audit Results Report. | G20: Attach a report documenting the results & outputs of each procedure implemented to monitor compliance. The compliance report shall include the following, at a minimum: • Compliance or Non-Compliance with each specification. • An explanation for compliance results with sufficient evidence for each specification. • Recommendations to remediate each instance of non-compliance. • Accountable stakeholder for each recommendation, and the target date to complete the recommendation. | H20: P2 | I20: DG.5.2 | J20: DG.C.5.2 | K20: Yes | L20: Yes | O20: SANS_NDMO Compliance Assessment Sheet | P20: Data Governance & Protection
A21: Data Governance | B21: DG | C21: DG.MQ.2 | D21: Managed | E21: 4 | F21: Compliance Monitoring Report. | G21: Attach a report(s) to confirm that the Entity has established and monitored compliance points by implementing a periodic compliance audit procedure. For the report to be accepted, it must be: • Compliant with the national framework for compliance in data management and governance. • Include compliance audit scores generated by the periodic compliance audits. | H21: P2 | I21: DG.5.3 | J21: DG.C.5.3 | K21: Under Development | L21: Yes | N21: NDMO assessment tool is being used for self-assessment | O21: SANS_NDMO Compliance Assessment Sheet | P21: Data Governance & Protection
A22: Data Governance | B22: DG | C22: DG.MQ.2 | D22: Pioneer | E22: 5 | F22: All level 4 acceptance evidence requirements including: - A report demonstrating the entity's innovative mechanisms for enabling compliance monitoring of DM & PDP Policies and Standards. | G22: The entity should attach the continuous improvement report for DM, DG, and PDP policies, based on the results of KPI measurements and relevant updates and developments. The report should include the following, at a minimum:  Conducted Reviews.  Results of each review.  Implemented improvements (with supporting documents).  Innovative mechanisms developed by the entity for enabling compliance monitoring of DM & PDP policies and standards. | H22: N/A | I22: N/A | J22: DG.M.6 | K22: N/A | L22: No | P22: Data Governance & Protection
A23: Data Governance | B23: DG | C23: DG.MQ.3 | D23: Establishing | E23: 1 | F23: The Entity's Data Management Office establishment decision. | G23: Attach the decision to establish a Data Management Office to supervise the implementation of the national strategy for DM, DG & PDP. To accept the attachment, the following requirements must be met:  The decision must be issued by the entity’s authority holder.  The Office’s responsibilities are documented in line with the “Organizational Manual”. | H23: P1 | I23: DG.4.1 | J23: DG.C.4.1 | K23: Yes | L23: Yes | N23: Evidence not found | O23: FW Organizational Announcement - Executives, FW Organizational Changes | P23: Data Governance & Protection
A24: Data Governance | B24: DG | C24: DG.MQ.3 | D24: Establishing | E24: 1 | F24: The appointment/hiring decisions for the following roles: A. Chief Data Officer (CDO) hiring/ appointment decision letter. | G24: To accept the attachment, the following requirements must be met:  The decision must be issued by the entity’s authority holder.  The CDO’s responsibilities are clarified in an approved job description.  The responsibilities are in line with the “Organizational Manual”. | H24: P1 | I24: DG.4.3 | J24: DG.C.4.3 | K24: Under Development | L24: Partially | N24: There is no designated individual appointed for the CDO role. however the CDO responsibilities are being carried out by the Cybersecurity, Data Governance, and Data Management Directors. There needs a confirmation from upper management regarding the decision, or documented within the target operating model | O24: Data Management Governance Committee Charter PMO, FW Organizational Announcement - Executives, Cybersecurity and Data Governance Director | P24: Data Governance & Protection
A25: Data Governance | B25: DG | C25: DG.MQ.3 | D25: Establishing | E25: 1 | F25: The appointment/hiring decisions for the following roles: B. Data Management Officer / Data Governance Officer Hiring / Appointment Decision. | G25: To accept the attachment, the following requirements must be met: • The decision must be issued by the Entity’s authority holder. • The Data Management Officer / Data Governance Officer’s responsibilities are clarified in an approved job description. • The responsibilities are in line with the "Organizational Manual”. | H25: P1 | I25: DG.4.4 | J25: DG.C.4.4 | K25: Yes | L25: Yes | O25: FW Organizational Announcement - Executives, Data Management Director V2 | P25: Data Governance & Protection
A26: Data Governance | B26: DG | C26: DG.MQ.3 | D26: Defined | E26: 2 | F26: All level 1 acceptance evidence requirements including: - Data Management & Governance Committee formation decision. | G26: To accept the attachment, the following requirements must be met:  The decision must be issued by the entity’s authority holder.  The Committee’s Charter including:  Roles and Responsibilities.  Rules of work for the committee. The decision letter must include a statement indicating that the committee's tasks involve providing guidance and overseeing the DM Strategy at the organizational level. | H26: P1 | I26: DG.4.2 | J26: DG.C.4.2 | K26: Yes | L26: Yes | O26: Data Management Governance Committee Charter PMO | P26: Data Governance & Protection
A27: Data Governance | B27: DG | C27: DG.MQ.3 | D27: Defined | E27: 2 | F27: The Hiring / Appointment decisions of the following roles: A. Compliance Officer Hiring / Appointment Decision. | G27: To accept the attachment, the following requirements must be met: • The decision must be issued by the Entity’s authority holder. • The Compliance Officer’s responsibilities are clarified in an approved job description. • The responsibilities are in line with the “Organizational Manual”. | H27: P1 | I27: DG.4.6 | J27: DG.C.4.6 | K27: Yes | L27: Yes | O27: CIS - Data Governance Section Head - updated, CIS - Data Governance and Compliance Specialist - Updated, CIS - Data Governance and Protection Manager - updated | P27: Data Governance & Protection
A28: Data Governance | B28: DG | C28: DG.MQ.3 | D28: Defined | E28: 2 | F28: The Hiring / Appointment decisions of the following roles: B. Business Data Executive Hiring / Appointment Decision. | G28: To accept the attachment, the following requirements must be met: • The decision must be issued by the Entity’s authority holder. • The Business Data Executive’s responsibilities are clarified in an approved job description. • The responsibilities are in line with the “Organizational Manual”. | H28: P1 | I28: DG.4.8 | J28: DG.C.4.8 | K28: Yes | L28: Yes | N28: Job Description exists within the target operating model, and the list of data owners have been identified. | O28: Business Data Owner & Stewards SANS_Target_State_Data_Operating_Model_v 4.0.pdf Steering Committee Presentation - 01272025 | P28: Data Governance & Protection
A29: Data Governance | B29: DG | C29: DG.MQ.3 | D29: Defined | E29: 2 | F29: The Hiring / Appointment decisions of the following roles: C. Legal Advisor Hiring / Appointment Decision. | G29: To accept the attachment, the following requirements must be met: • The decision must be issued by the Entity’s authority holder. • The Legal Advisor’s responsibilities are clarified in an approved job description. • The responsibilities are in line with the “Organizational Manual”. | H29: P1 | I29: DG.4.11 | J29: DG.C.4.11 | K29: Yes | L29: Yes | N29: Though Role exists, it needs to be clearly defined within the operating model | O29: CEO - Legal Consultations & Contracts Section Head, CEO - Legal Manager, CEO - Litigations Section Head | P29: Data Governance & Protection
A30: Data Governance | B30: DG | C30: DG.MQ.3 | D30: Activated | E30: 3 | F30: All level 2 acceptance evidence requirements including: - The Hiring / Appointment decisions of the following roles: A. Business Data Steward(s) Hiring / Appointment Decision. | G30: To accept the attachment, the following requirements must be met: • The decision must be issued by the Entity’s authority holder. • The Business Data Steward’s responsibilities are clarified in an approved job description. • The responsibilities are in line with the “Organizational Manual”. | H30: P1 | I30: DG.4.9 | J30: DG.C.4.9 | K30: Under Development | L30: Partially | N30: Job Description exists within the target operating model, and the list of business stewards have been identified,. However, the data steward list will need to be updated, and approved by upper management (formal endorsement from the committee) | O30: Business Data Owner & Stewards SANS_Target_State_Data_Operating_Model_v 4.0.pdf | P30: Data Governance & Protection
A31: Data Governance | B31: DG | C31: DG.MQ.3 | D31: Activated | E31: 3 | F31: The Hiring / Appointment decisions of the following roles: B. List of the IT Data Stewards. | G31: To accept the attachment, the following requirements must be met: • The decision must be issued by the Entity’s authority holder. • The IT Data Steward’s responsibilities are clarified in an approved job description. • The responsibilities are in line with the Organizational Manual. | H31: P1 | I31: DG.4.10 | J31: DG.C.4.10 | K31: Under Development | L31: Partially | N31: Currently technical stewards are not appointed by systems. | O31: Business Data Owner & Stewards SANS_Target_State_Data_Operating_Model_v 4.0.pdf | P31: Data Governance & Protection
A32: Data Governance | B32: DG | C32: DG.MQ.3 | D32: Activated | E32: 3 | F32: The Hiring / Appointment decisions of the following roles: C. Personal Data Protection (PDP) Officer Hiring / Appointment Decision. | G32: To accept the attachment, the following requirements must be met: • The decision must be issued by the Entity’s authority holder. • The PDP Officer’s responsibilities are clarified in an approved job description. • The responsibilities are in line with the Organizational Manual. | H32: P1 | I32: DG.4.7 | J32: DG.C.4.7 | K32: Yes | L32: Yes | N32: Job description Data Protection and Privacy section Head has been developed and approved, with additional roles as well | O32: CIS - Data Governance and Protection Manager - updated, CIS - Data Protection and Privacy Section head, CIS - Data Protection Specialist | P32: Data Governance & Protection
A33: Data Governance | B33: DG | C33: DG.MQ.3 | D33: Activated | E33: 3 | F33: The Hiring / Appointment decisions of the following roles: D. Open Data and Information Access Officer Hiring / Appointment Decision. | G33: To accept the attachment, the following requirements must be met:  The decision must be issued by the entity’s authority holder.  The ODIAO’s responsibilities are clarified in an approved job description.  The responsibilities are in line with the Organizational Manual. | H33: P1 | I33: DG.4.5 | J33: DG.C.4.5 | K33: Under Development | L33: Partially | N33: There is no appointed Open Data and Information Access Officer; responsibilities are managed by the Data Governance and Compliance Specialist per the approved job description. There needs a confirmation from upper management regarding the decision, or documented within the target operating model | O33: CIS - Data Governance and Compliance Specialist - Updated, CIS - Data Governance Section Head - updated | P33: Data Governance & Protection
A34: Data Governance | B34: DG | C34: DG.MQ.3 | D34: Activated | E34: 3 | F34: The documented & approved Data Management Organization structure. | G34: Attach the documented & approved Data Management Organization structure, including the following, as a minimum: • Roles & responsibilities. • Approved job descriptions for each role. • Authorization: Reviews, approvals and decision making. | H34: N/A | I34: N/A | J34: DG.M.7 | K34: N/A | L34: No | P34: Data Governance & Protection
A35: Data Governance | B35: DG | C35: DG.MQ.3 | D35: Activated | E35: 3 | F35: The documented Data Stewardship / Ownership structure. | G35: Attach the documented & approved Data Stewardship / Data Ownership structure, including the following, as a minimum: • Identified Data Domains. • Business Data Executives for each Data Domain. • Business Data Steward for each Data Domain. • IT Data Steward for each Data Domain. • Roles & responsibilities. | H35: N/A | I35: N/A | J35: DG.M.8 | K35: N/A | L35: No | P35: Data Governance & Protection
A36: Data Governance | B36: DG | C36: DG.MQ.3 | D36: Managed | E36: 4 | F36: All level 3 acceptance evidence requirements including - The monitoring reports for the entity's Data Management Organization roles based on the pre_x0002_defined KPIs in the strategy and implementation plan. | G36: The entity should attach an updated report approved by the entity’s authority holder to measure the entity’s performance in monitoring job roles based on the identified and pre_x0002_defined Key Performance Indicators (KPIs) and scorecards. Each indicator’s card should include the following, at a minimum: • Indicator’s Name / Code. • Indicator’s Owner. • Indicator’s Coordinator. • Indicator’s Description. • The strategic/operational objective to be measured (with identifying the Specification or the Process to which the indicator belongs). • Indicator’s Equation. • Measurement Unit (Percentage, Number / Quantity, etc.). • Baseline (Measurement value in the first measurement year). • Target value. • Measurement Periodicity (Monthly / Quarterly / Biannually / Annually). • Data sources used to calculate the indicator. • Data collection mechanism. • Indicator’s polarity (+/-) (Positive Polarity: Higher indicator value is the target, Negative Polarity: Lower indicator value is the target). • The current value of the indicator compared to the target value. • The status of the indicator (achieved/delayed/not achieved/etc). The report should also include: • Recommendations for performance improvement based on the actual values of the indicators. • Supporting documents for the data used to calculate the indicator values. | H36: P2 | I36: DG.7.1 (KPI 1) | J36: DG.C.7.1 .2 | K36: Under Development | L36: Partially | M36: 1 | N36: The KPIs have been defined as part of the strategy, however the KPIs are not tracked | P36: Data Governance & Protection
A37: Data Governance | B37: DG | C37: DG.MQ.3 | D37: Pioneer | E37: 5 | F37: All level 4 acceptance evidence requirements including: - Continuous improvement report for the roles and responsibilities of Data Management Organization within the entity. | G37: The entity must attach the continuous improvement report for the roles and responsibilities of DM Organization within the entity. The report should include the following, at a minimum:  Conducted Reviews.  Results of each review.  Implemented improvements (with supporting documents). | H37: N/A | I37: N/A | J37: DG.M.9 | K37: N/A | L37: No | P37: Data Governance & Protection
A38: Data Governance | B38: DG | C38: DG.MQ.4 | D38: Establishing | E38: 1 | F38: Evidences of communication on DM-related practices. | G38: Attach evidences showing that the entity has communications regarding Data Management practices, such as: • E-mails. • Correspondences. | H38: N/A | I38: N/A | J38: DG.M.10 | K38: N/A | L38: Yes | O38: RE_ Data Management & NDMO Requirements - Content Management, NDMO Requirements Socialization – Crisis Management & Business Continuity Team, Fw_ NDMO Requirements Details | P38: Data Governance & Protection
A39: Data Governance | B39: DG | C39: DG.MQ.4 | D39: Establishing | E39: 1 | F39: Evidences of training and awareness sessions conducted. | G39: Attach a report on the training courses & awareness programs implemented by the Entity, including the following, as a minimum: • Names of the implemented training courses related to DM, DG & PDP. • Awareness programs implemented in the different Domains under DM, DG & PDP. • A certificate of attendance sample for training the Entity’s employees in Domains related to DM, DG & PDP. | H39: N/A | I39: N/A | J39: DG.M.11 | K39: N/A | L39: Partially | N39: Training Content Created, but no tracking or list has been developed that mentions the trainings | O39: SANS Data Management Training v4 (1), SANS_Data Classification Awareness - Final Version (005) | P39: Data Governance & Protection
A40: Data Governance | B40: DG | C40: DG.MQ.4 | D40: Defined | E40: 2 | F40: All level 1 acceptance evidence requirements including: - The Change Management Plan. | G40: The Change Management Plan covering all DM Domains including: • The DM & PDP Training Plan for all DM Domains. • The DM Communication plan. • The Stakeholders engagement plan. • The Change Control plan for Data system changes. | H40: N/A | I40: N/A | J40: DG.M.12 | K40: N/A | L40: No | P40: Data Governance & Protection
A41: Data Governance | B41: DG | C41: DG.MQ.4 | D41: Activated | E41: 3 | F41: All level 2 acceptance evidence requirements including: - The Change Management Implementation Status Report showing the DM & PDP Training & Awareness Activities. | G41: Attach a report on the implementation status of the change management plan, and the report must include, as a minimum: • The DM & PDP Training implementation status for all DM Domains showing: • Evidences of training conducted for the Entity’s employees, covering all DM Domains. • A list of activities carried out by the Entity to raise awareness regarding the national regulations, laws, policies & controls, standards and their applicability (such as: e-mails, publications, lectures, workshops, etc.). • A list of activities carried out by the Entity to raise awareness regarding the national DM, DG & PDP strategy and programs and their applicability on the Entity (such as: e-mails, publications, lectures, workshops, etc.). • A list of activities carried out by the Entity to raise awareness regarding the data management domains as per the National Data Management and Personal Data Protection Framework, addressed to the related Data Management and Personal Data Protection roles. | H41: P1 | I41: DG.3.1 | J41: DG.C.3.1 | K41: Under Development | L41: No | N41: Training conducted to full time roles, but not part time roles (Data Owners, Stewards) | P41: Data Governance & Protection
A42: Data Governance | B42: DG | C42: DG.MQ.4 | D42: Activated | E42: 3 | F42: The Change Management Implementation Status Report showing the DM Communication activities. | G42: Attach a report on the implementation status of the change management plan, and the report must include evidences confirming the Entity's continuous communication regarding the following: • The DM, DG & PDP Program, activities and main decisions. • The storage of DM & DG documents & artifacts. • The measurement of DM & DG performance indicators. • The updates on DM & DG policies & processes. • The updates on compliance reports, implementation plans, and the regulatory (legislative) environment related to DM & DG. | H42: P2 | I42: DG.6.2 | J42: DG.C.6.2 | K42: No | L42: No | P42: Data Governance & Protection
A43: Data Governance | B43: DG | C43: DG.MQ.4 | D43: Activated | E43: 3 | F43: The Stakeholders Engagement and Socialization plan implementation status report. | G43: Attach a report showing that the Entity is engaging the identified stakeholders to develop and improve on the capabilities of the DM & PDP program. | H43: P1 | I43: DG.1.4 | J43: DG.C.1.4.2 | K43: Yes | L43: Yes | M43: 1 | O43: RE_ Data Management & NDMO Requirements - Content Management, NDMO Requirements Socialization – Crisis Management & Business Continuity Team, Fw_ NDMO Requirements Details | P43: Data Governance & Protection
...

Sheet Maturity Questions Overview
B2: Maturity Questions
B3: Domain | C3: ID | D3: Question | E3: Maturity Level | K3: Maturity Level per Question
E4: Level 0 | F4: Level 1 | G4: Level 2 | H4: Level 3 | I4: Level 4 | J4: Level 5
E5: Absence of Capabilities | F5: Establishing | G5: Defined | H5: Activated | I5: Managed | J5: Pioneer
B6: Data Governance | C6: DG.MQ.1 | D6: Has the Entity established & implemented a Data Management & Personal Data Protection (DM & PDP) Strategy and a DM & PDP Plan with Key Performance Indicators (KPIs) that can be continuously measured to ensure optimization? | E6: No Data Management & Personal Data Protection (DM & PDP) strategy is in place. | F6: The Entity has existing DM practices that are not formalized (not approved). | G6: • A cross-Entity DM & PDP strategy is defined for all DM Domains. • DM Guiding principles have been developed. | H6: • The Entity developed a DM & PDP plan based on the defined DM & PDP strategy. • The Entity is implementing this DM & PDP plan which covers all DM Domains. | I6: The Entity is monitoring the DM & PDP strategy & plan implementation across all DM Domains with the pre-defined KPIs. | J6: • The DM & PDP strategy is periodically updated, improved and optimized across all DM Domains. • The DM & PDP implementation plan is periodically reviewed and updated based on both the changes to the DM & PDP strategy and the changing business requirements. | K6: =VLOOKUP(C6, Calculation!$T$3:$AA$45,8,FALSE) -> 2
C7: DG.MQ.2 | D7: Has the Entity established and implemented Data Management (DM) Policies, Standards and Guidelines across all Data Management (DM) Domains? | E7: No Data Management (DM) Policies, Standards or Guidelines are in place. | F7: • The Entity has existing DM-related policies and standards that are not formalized. • The Entity conducted a gap analysis to identify the required DM and PDP policies to be developed | G7: The Entity developed policies, standards and guidelines for all DM Domains. | H7: The Entity is implementing the developed DM and PDP policies with defined processes and standards to establish governance, uniformity and manage compliance across the Entity. | I7: • The DM and PDP policies, standards and processes are tracked and measured based on the pre-defined KPIs. • Periodic monitoring is conducted on the Entity's compliance with the Regulations published by NDMO-SDAIA. | J7: The DM and PDP policies, standards, DG processes and compliance with regulations are continuously reviewed and optimized. | K7: =VLOOKUP(C7, Calculation!$T$3:$AA$45,8,FALSE) -> 1
C8: DG.MQ.3 | D8: Has the Entity established and operationalized all roles required for the Data Management Organization as per the NDMO Controls & Specifications? | E8: No formal/approved Data Management Organization structure is in place. | F8: The Entity established a Data Management Office with one or two roles only. | G8: The Entity "Data Management & Data Governance Committee" (An internal executive committee) is established with a total of six roles (out of the DM Office roles) assigned & operationalized for the Data Management Organization. | H8: • All DM roles are established as per the DM and PDP Standards and fully adopted across the Entity. • Data Stewardship / Ownership defined across the Entity, in addition to providing business and technical support for critical Data systems & critical Data elements. | I8: • The Data Management Organization & the structure are fully established and operationalized. • The roles are tracked through pre-defined KPIs, periodically updated and optimized. | J8: Data Management Organization (& its structure) and Data stewardship (& its structure) (Data owners, business and technical stewards) are periodically reviewed and updated. | K8: =VLOOKUP(C8, Calculation!$T$3:$AA$45,8,FALSE) -> 0
C9: DG.MQ.4 | D9: Has the Entity established and implemented practices for Change Management including awareness, communication, change control, and capability development? | E9: No formal Change Management practices are in place. | F9: • Awareness sessions, training courses and communication on DM-related practices are performed on a reactive and ad-hoc basis. • The Entity has change control practices that are not formalized. | G9: • The Entity has defined Change Management practices. • There is an Entity-wide awareness, training and communication plan. • Change control practices are established to ensure coordinated efforts in managing changes on Data systems (implemented within the Entity). | H9: • The Entity is implementing the defined Change Management practices for all DM Domains. • Formal communication channels are established and adopted for DM issues management, escalations, resolutions & approvals. • A Version control mechanism is defined and implemented for DM documents and artifacts that the Entity published. • The DM & PDP Strategy is being socialized and awareness is conducted across the Entity. | I9: The Entity is monitoring the progress and the effectiveness of the Change Management practices with pre-defined KPIs. | J9: Change Management practices for all DM Domains are periodically reviewed, and continuously updated, optimized & developed. | K9: =VLOOKUP(C9, Calculation!$T$3:$AA$45,8,FALSE) -> 0
B10: Metadata & Data Catalog | C10: MCM.MQ.1 | D10: Has the Entity developed and implemented a plan to integrate and manage Metadata across the Entity? | E10: No plan is in place to integrate and manage Metadata in the Entity. | F10: The Entity manages its Metadata on a reactive and ad hoc basis. | G10: • The Entity developed a plan, an operating model and a structure for the implementation of Metadata and Data Catalog. • The Metadata management structure should include the requirements to capture, integrate, populate, publish and utilize the required technology solution for the Entity's Metadata (business and technical). • A roadmap is defined with a list of activities, required resources, and a budget to manage the Data Catalog and Metadata implementation. | H10: • The Entity is implementing the defined Metadata and Data Catalog plan and framework. • This implementation includes the identification and prioritization of the critical systems and attributes. | I10: The Entity is monitoring the effectiveness of the Metadata and Data Catalog plan and activities with pre-defined Key Performance Indicators (KPIs). | J10: The Metadata and Data Catalog plan and activities are regularly monitored for continuous improvement and optimization. | K10: =VLOOKUP(C10, Calculation!$T$3:$AA$45,8,FALSE) -> 0
C11: MCM.MQ.2 | D11: Has the Entity implemented a Metadata Management and Data Catalog tool / solution? | E11: No tools are in place to manage the Entity's Metadata. | F11: The Entity manages its Metadata manually or in standalone applications without standardized tools. | G11: • The Entity documented its requirements for the Data Catalog tool / solution and selected an appropriate tool based on business and regulatory requirements. • The Entity's data sources to be included in the Data Catalog tool have been identified and prioritized. • The Entity developed a target Metadata architecture. | H11: • The Data Catalog tool has been implemented and populated with the Entity’s Metadata. • The tool is integrated into the Entity’s Metadata repository with appropriate access permissions. • The tool stores the activities and tracking logs for Audit Trails. • Power users are identified and trained on the Data Catalog tool usage. • A training and communication plan is rolled out to raise awareness and adoption of the Data Catalog tool. • The Data catalog automated tool is regularly updated to the latest version. | I11: • The Entity is monitoring changes to its Metadata through automated notifications. • The adoption and usage of the implemented Data Catalog tool is closely monitored based on a set of pre-defined Key Performance Indicators (KPIs). | J11: • The Entity has fully automated end-to-end Metadata (Business, Technical, and Operational) capture and exchange. • The Entity continuously monitors and optimizes the Data Catalog. • The Entity continuously updates the Data Catalog in the event of any changes specified by the National Data Bank (NDB). | K11: =VLOOKUP(C11, Calculation!$T$3:$AA$45,8,FALSE) -> 0
